Many modules are hidden in this stack. Use "module --show_hidden spider SOFTWARE" if you are not able to find the required software
Traceback (most recent call last):
  File "/cluster/software/stacks/2024-06/spack/opt/spack/linux-ubuntu22.04-x86_64_v3/gcc-12.2.0/python-3.11.6-ukhwpjnwzzzizek3pgr75zkbhxros5fq/lib/python3.11/site-packages/urllib3/connection.py", line 196, in _new_conn
    sock = connection.create_connection(
           ^^^^^^^^^^^^^^^^^^^^^^^^^^^^^
  File "/cluster/software/stacks/2024-06/spack/opt/spack/linux-ubuntu22.04-x86_64_v3/gcc-12.2.0/python-3.11.6-ukhwpjnwzzzizek3pgr75zkbhxros5fq/lib/python3.11/site-packages/urllib3/util/connection.py", line 85, in create_connection
    raise err
  File "/cluster/software/stacks/2024-06/spack/opt/spack/linux-ubuntu22.04-x86_64_v3/gcc-12.2.0/python-3.11.6-ukhwpjnwzzzizek3pgr75zkbhxros5fq/lib/python3.11/site-packages/urllib3/util/connection.py", line 73, in create_connection
    sock.connect(sa)
ConnectionRefusedError: [Errno 111] Connection refused

The above exception was the direct cause of the following exception:

Traceback (most recent call last):
  File "/cluster/software/stacks/2024-06/spack/opt/spack/linux-ubuntu22.04-x86_64_v3/gcc-12.2.0/python-3.11.6-ukhwpjnwzzzizek3pgr75zkbhxros5fq/lib/python3.11/site-packages/urllib3/connectionpool.py", line 789, in urlopen
    response = self._make_request(
               ^^^^^^^^^^^^^^^^^^^
  File "/cluster/software/stacks/2024-06/spack/opt/spack/linux-ubuntu22.04-x86_64_v3/gcc-12.2.0/python-3.11.6-ukhwpjnwzzzizek3pgr75zkbhxros5fq/lib/python3.11/site-packages/urllib3/connectionpool.py", line 490, in _make_request
    raise new_e
  File "/cluster/software/stacks/2024-06/spack/opt/spack/linux-ubuntu22.04-x86_64_v3/gcc-12.2.0/python-3.11.6-ukhwpjnwzzzizek3pgr75zkbhxros5fq/lib/python3.11/site-packages/urllib3/connectionpool.py", line 466, in _make_request
    self._validate_conn(conn)
  File "/cluster/software/stacks/2024-06/spack/opt/spack/linux-ubuntu22.04-x86_64_v3/gcc-12.2.0/python-3.11.6-ukhwpjnwzzzizek3pgr75zkbhxros5fq/lib/python3.11/site-packages/urllib3/connectionpool.py", line 1095, in _validate_conn
    conn.connect()
  File "/cluster/software/stacks/2024-06/spack/opt/spack/linux-ubuntu22.04-x86_64_v3/gcc-12.2.0/python-3.11.6-ukhwpjnwzzzizek3pgr75zkbhxros5fq/lib/python3.11/site-packages/urllib3/connection.py", line 615, in connect
    self.sock = sock = self._new_conn()
                       ^^^^^^^^^^^^^^^^
  File "/cluster/software/stacks/2024-06/spack/opt/spack/linux-ubuntu22.04-x86_64_v3/gcc-12.2.0/python-3.11.6-ukhwpjnwzzzizek3pgr75zkbhxros5fq/lib/python3.11/site-packages/urllib3/connection.py", line 211, in _new_conn
    raise NewConnectionError(
urllib3.exceptions.NewConnectionError: <urllib3.connection.HTTPSConnection object at 0x15249aafa590>: Failed to establish a new connection: [Errno 111] Connection refused

The above exception was the direct cause of the following exception:

Traceback (most recent call last):
  File "/cluster/software/stacks/2024-06/spack/opt/spack/linux-ubuntu22.04-x86_64_v3/gcc-12.2.0/python-3.11.6-ukhwpjnwzzzizek3pgr75zkbhxros5fq/lib/python3.11/site-packages/requests/adapters.py", line 667, in send
    resp = conn.urlopen(
           ^^^^^^^^^^^^^
  File "/cluster/software/stacks/2024-06/spack/opt/spack/linux-ubuntu22.04-x86_64_v3/gcc-12.2.0/python-3.11.6-ukhwpjnwzzzizek3pgr75zkbhxros5fq/lib/python3.11/site-packages/urllib3/connectionpool.py", line 843, in urlopen
    retries = retries.increment(
              ^^^^^^^^^^^^^^^^^^
  File "/cluster/software/stacks/2024-06/spack/opt/spack/linux-ubuntu22.04-x86_64_v3/gcc-12.2.0/python-3.11.6-ukhwpjnwzzzizek3pgr75zkbhxros5fq/lib/python3.11/site-packages/urllib3/util/retry.py", line 519, in increment
    raise MaxRetryError(_pool, url, reason) from reason  # type: ignore[arg-type]
    ^^^^^^^^^^^^^^^^^^^^^^^^^^^^^^^^^^^^^^^^^^^^^^^^^^^
urllib3.exceptions.MaxRetryError: HTTPSConnectionPool(host='cloud.pennylane.ai', port=443): Max retries exceeded with url: /graphql (Caused by NewConnectionError('<urllib3.connection.HTTPSConnection object at 0x15249aafa590>: Failed to establish a new connection: [Errno 111] Connection refused'))

During handling of the above exception, another exception occurred:

Traceback (most recent call last):
  File "/cluster/home/forazi/Dim_red_SWAP/Cluster/get_data.py", line 2, in <module>
    data=get_data(4)
         ^^^^^^^^^^^
  File "/cluster/home/forazi/Dim_red_SWAP/Cluster/utils.py", line 439, in get_data
    data = qml.data.load("qspin", 
           ^^^^^^^^^^^^^^^^^^^^^^
  File "/cluster/home/forazi/.local/lib/python3.11/site-packages/pennylane/data/data_manager/__init__.py", line 344, in load
    dataset_ids_and_urls = get_dataset_urls(data_name, params)
                           ^^^^^^^^^^^^^^^^^^^^^^^^^^^^^^^^^^^
  File "/cluster/home/forazi/.local/lib/python3.11/site-packages/pennylane/data/data_manager/graphql.py", line 57, in get_dataset_urls
    response = get_graphql(
               ^^^^^^^^^^^^
  File "/cluster/home/forazi/.local/lib/python3.11/site-packages/pennylane/data/data_manager/graphql.py", line 34, in get_graphql
    response = post(url=url, json=json, timeout=10, headers={"content-type": "application/json"})
               ^^^^^^^^^^^^^^^^^^^^^^^^^^^^^^^^^^^^^^^^^^^^^^^^^^^^^^^^^^^^^^^^^^^^^^^^^^^^^^^^^^
  File "/cluster/software/stacks/2024-06/spack/opt/spack/linux-ubuntu22.04-x86_64_v3/gcc-12.2.0/python-3.11.6-ukhwpjnwzzzizek3pgr75zkbhxros5fq/lib/python3.11/site-packages/requests/api.py", line 115, in post
    return request("post", url, data=data, json=json, **kwargs)
           ^^^^^^^^^^^^^^^^^^^^^^^^^^^^^^^^^^^^^^^^^^^^^^^^^^^^
  File "/cluster/software/stacks/2024-06/spack/opt/spack/linux-ubuntu22.04-x86_64_v3/gcc-12.2.0/python-3.11.6-ukhwpjnwzzzizek3pgr75zkbhxros5fq/lib/python3.11/site-packages/requests/api.py", line 59, in request
    return session.request(method=method, url=url, **kwargs)
           ^^^^^^^^^^^^^^^^^^^^^^^^^^^^^^^^^^^^^^^^^^^^^^^^^
  File "/cluster/software/stacks/2024-06/spack/opt/spack/linux-ubuntu22.04-x86_64_v3/gcc-12.2.0/python-3.11.6-ukhwpjnwzzzizek3pgr75zkbhxros5fq/lib/python3.11/site-packages/requests/sessions.py", line 589, in request
    resp = self.send(prep, **send_kwargs)
           ^^^^^^^^^^^^^^^^^^^^^^^^^^^^^^
  File "/cluster/software/stacks/2024-06/spack/opt/spack/linux-ubuntu22.04-x86_64_v3/gcc-12.2.0/python-3.11.6-ukhwpjnwzzzizek3pgr75zkbhxros5fq/lib/python3.11/site-packages/requests/sessions.py", line 703, in send
    r = adapter.send(request, **kwargs)
        ^^^^^^^^^^^^^^^^^^^^^^^^^^^^^^^
  File "/cluster/software/stacks/2024-06/spack/opt/spack/linux-ubuntu22.04-x86_64_v3/gcc-12.2.0/python-3.11.6-ukhwpjnwzzzizek3pgr75zkbhxros5fq/lib/python3.11/site-packages/requests/adapters.py", line 700, in send
    raise ConnectionError(e, request=request)
requests.exceptions.ConnectionError: HTTPSConnectionPool(host='cloud.pennylane.ai', port=443): Max retries exceeded with url: /graphql (Caused by NewConnectionError('<urllib3.connection.HTTPSConnection object at 0x15249aafa590>: Failed to establish a new connection: [Errno 111] Connection refused'))
srun: error: eu-g9-048-4: task 0: Exited with exit code 1
