Many modules are hidden in this stack. Use "module --show_hidden spider SOFTWARE" if you are not able to find the required software
Traceback (most recent call last):
  File "/cluster/software/stacks/2024-06/spack/opt/spack/linux-ubuntu22.04-x86_64_v3/gcc-12.2.0/python-3.11.6-ukhwpjnwzzzizek3pgr75zkbhxros5fq/lib/python3.11/site-packages/seaborn/_base.py", line 1768, in categorical_order
    order = vector.cat.categories
            ^^^^^^^^^^
  File "/cluster/software/stacks/2024-06/spack/opt/spack/linux-ubuntu22.04-x86_64_v3/gcc-12.2.0/python-3.11.6-ukhwpjnwzzzizek3pgr75zkbhxros5fq/lib/python3.11/site-packages/pandas/core/generic.py", line 6299, in __getattr__
    return object.__getattribute__(self, name)
           ^^^^^^^^^^^^^^^^^^^^^^^^^^^^^^^^^^^
  File "/cluster/software/stacks/2024-06/spack/opt/spack/linux-ubuntu22.04-x86_64_v3/gcc-12.2.0/python-3.11.6-ukhwpjnwzzzizek3pgr75zkbhxros5fq/lib/python3.11/site-packages/pandas/core/accessor.py", line 224, in __get__
    accessor_obj = self._accessor(obj)
                   ^^^^^^^^^^^^^^^^^^^
  File "/cluster/software/stacks/2024-06/spack/opt/spack/linux-ubuntu22.04-x86_64_v3/gcc-12.2.0/python-3.11.6-ukhwpjnwzzzizek3pgr75zkbhxros5fq/lib/python3.11/site-packages/pandas/core/arrays/categorical.py", line 2898, in __init__
    self._validate(data)
  File "/cluster/software/stacks/2024-06/spack/opt/spack/linux-ubuntu22.04-x86_64_v3/gcc-12.2.0/python-3.11.6-ukhwpjnwzzzizek3pgr75zkbhxros5fq/lib/python3.11/site-packages/pandas/core/arrays/categorical.py", line 2907, in _validate
    raise AttributeError("Can only use .cat accessor with a 'category' dtype")
AttributeError: Can only use .cat accessor with a 'category' dtype. Did you mean: 'at'?

During handling of the above exception, another exception occurred:

Traceback (most recent call last):
  File "/cluster/home/forazi/Dim_red_SWAP/Cluster/single_run.py", line 171, in <module>
  File "/cluster/home/forazi/Dim_red_SWAP/Cluster/single_run.py", line 118, in main
    plt.legend(title='Batch size')
    ^^^^^^^^^^^^^^^^^^^^^^^^^^^^^^^
  File "/cluster/software/stacks/2024-06/spack/opt/spack/linux-ubuntu22.04-x86_64_v3/gcc-12.2.0/python-3.11.6-ukhwpjnwzzzizek3pgr75zkbhxros5fq/lib/python3.11/site-packages/seaborn/relational.py", line 508, in lineplot
    p._attach(ax)
  File "/cluster/software/stacks/2024-06/spack/opt/spack/linux-ubuntu22.04-x86_64_v3/gcc-12.2.0/python-3.11.6-ukhwpjnwzzzizek3pgr75zkbhxros5fq/lib/python3.11/site-packages/seaborn/_base.py", line 1134, in _attach
    seed_data = categorical_order(seed_data, order)
                ^^^^^^^^^^^^^^^^^^^^^^^^^^^^^^^^^^^
  File "/cluster/software/stacks/2024-06/spack/opt/spack/linux-ubuntu22.04-x86_64_v3/gcc-12.2.0/python-3.11.6-ukhwpjnwzzzizek3pgr75zkbhxros5fq/lib/python3.11/site-packages/seaborn/_base.py", line 1771, in categorical_order
    order = pd.Series(vector).unique()
            ^^^^^^^^^^^^^^^^^^^^^^^^^^
  File "/cluster/software/stacks/2024-06/spack/opt/spack/linux-ubuntu22.04-x86_64_v3/gcc-12.2.0/python-3.11.6-ukhwpjnwzzzizek3pgr75zkbhxros5fq/lib/python3.11/site-packages/pandas/core/series.py", line 2407, in unique
    return super().unique()
           ^^^^^^^^^^^^^^^^
  File "/cluster/software/stacks/2024-06/spack/opt/spack/linux-ubuntu22.04-x86_64_v3/gcc-12.2.0/python-3.11.6-ukhwpjnwzzzizek3pgr75zkbhxros5fq/lib/python3.11/site-packages/pandas/core/base.py", line 1025, in unique
    result = algorithms.unique1d(values)
             ^^^^^^^^^^^^^^^^^^^^^^^^^^^
  File "/cluster/software/stacks/2024-06/spack/opt/spack/linux-ubuntu22.04-x86_64_v3/gcc-12.2.0/python-3.11.6-ukhwpjnwzzzizek3pgr75zkbhxros5fq/lib/python3.11/site-packages/pandas/core/algorithms.py", line 401, in unique
    return unique_with_mask(values)
           ^^^^^^^^^^^^^^^^^^^^^^^^
  File "/cluster/software/stacks/2024-06/spack/opt/spack/linux-ubuntu22.04-x86_64_v3/gcc-12.2.0/python-3.11.6-ukhwpjnwzzzizek3pgr75zkbhxros5fq/lib/python3.11/site-packages/pandas/core/algorithms.py", line 440, in unique_with_mask
    uniques = table.unique(values)
              ^^^^^^^^^^^^^^^^^^^^
  File "pandas/_libs/hashtable_class_helper.pxi", line 7248, in pandas._libs.hashtable.PyObjectHashTable.unique
  File "pandas/_libs/hashtable_class_helper.pxi", line 7195, in pandas._libs.hashtable.PyObjectHashTable._unique
TypeError: unhashable type: 'jaxlib.xla_extension.ArrayImpl'
srun: error: eu-g9-043-2: task 0: Exited with exit code 1
srun: Job 17971929 step creation temporarily disabled, retrying (Requested nodes are busy)
srun: Step created for StepId=17971929.1
Traceback (most recent call last):
  File "/cluster/software/stacks/2024-06/spack/opt/spack/linux-ubuntu22.04-x86_64_v3/gcc-12.2.0/python-3.11.6-ukhwpjnwzzzizek3pgr75zkbhxros5fq/lib/python3.11/site-packages/seaborn/_base.py", line 1768, in categorical_order
    order = vector.cat.categories
            ^^^^^^^^^^
  File "/cluster/software/stacks/2024-06/spack/opt/spack/linux-ubuntu22.04-x86_64_v3/gcc-12.2.0/python-3.11.6-ukhwpjnwzzzizek3pgr75zkbhxros5fq/lib/python3.11/site-packages/pandas/core/generic.py", line 6299, in __getattr__
    return object.__getattribute__(self, name)
           ^^^^^^^^^^^^^^^^^^^^^^^^^^^^^^^^^^^
  File "/cluster/software/stacks/2024-06/spack/opt/spack/linux-ubuntu22.04-x86_64_v3/gcc-12.2.0/python-3.11.6-ukhwpjnwzzzizek3pgr75zkbhxros5fq/lib/python3.11/site-packages/pandas/core/accessor.py", line 224, in __get__
    accessor_obj = self._accessor(obj)
                   ^^^^^^^^^^^^^^^^^^^
  File "/cluster/software/stacks/2024-06/spack/opt/spack/linux-ubuntu22.04-x86_64_v3/gcc-12.2.0/python-3.11.6-ukhwpjnwzzzizek3pgr75zkbhxros5fq/lib/python3.11/site-packages/pandas/core/arrays/categorical.py", line 2898, in __init__
    self._validate(data)
  File "/cluster/software/stacks/2024-06/spack/opt/spack/linux-ubuntu22.04-x86_64_v3/gcc-12.2.0/python-3.11.6-ukhwpjnwzzzizek3pgr75zkbhxros5fq/lib/python3.11/site-packages/pandas/core/arrays/categorical.py", line 2907, in _validate
    raise AttributeError("Can only use .cat accessor with a 'category' dtype")
AttributeError: Can only use .cat accessor with a 'category' dtype. Did you mean: 'at'?

During handling of the above exception, another exception occurred:

Traceback (most recent call last):
  File "/cluster/home/forazi/Dim_red_SWAP/Cluster/single_run.py", line 170, in <module>
    main()
  File "/cluster/home/forazi/Dim_red_SWAP/Cluster/single_run.py", line 117, in main
    sns.lineplot(x=range(len(val_loss)), y=val_loss, label='validation loss' ,color='#007162',linestyle=':')
  File "/cluster/software/stacks/2024-06/spack/opt/spack/linux-ubuntu22.04-x86_64_v3/gcc-12.2.0/python-3.11.6-ukhwpjnwzzzizek3pgr75zkbhxros5fq/lib/python3.11/site-packages/seaborn/relational.py", line 508, in lineplot
    p._attach(ax)
  File "/cluster/software/stacks/2024-06/spack/opt/spack/linux-ubuntu22.04-x86_64_v3/gcc-12.2.0/python-3.11.6-ukhwpjnwzzzizek3pgr75zkbhxros5fq/lib/python3.11/site-packages/seaborn/_base.py", line 1134, in _attach
    seed_data = categorical_order(seed_data, order)
                ^^^^^^^^^^^^^^^^^^^^^^^^^^^^^^^^^^^
  File "/cluster/software/stacks/2024-06/spack/opt/spack/linux-ubuntu22.04-x86_64_v3/gcc-12.2.0/python-3.11.6-ukhwpjnwzzzizek3pgr75zkbhxros5fq/lib/python3.11/site-packages/seaborn/_base.py", line 1771, in categorical_order
    order = pd.Series(vector).unique()
            ^^^^^^^^^^^^^^^^^^^^^^^^^^
  File "/cluster/software/stacks/2024-06/spack/opt/spack/linux-ubuntu22.04-x86_64_v3/gcc-12.2.0/python-3.11.6-ukhwpjnwzzzizek3pgr75zkbhxros5fq/lib/python3.11/site-packages/pandas/core/series.py", line 2407, in unique
    return super().unique()
           ^^^^^^^^^^^^^^^^
  File "/cluster/software/stacks/2024-06/spack/opt/spack/linux-ubuntu22.04-x86_64_v3/gcc-12.2.0/python-3.11.6-ukhwpjnwzzzizek3pgr75zkbhxros5fq/lib/python3.11/site-packages/pandas/core/base.py", line 1025, in unique
    result = algorithms.unique1d(values)
             ^^^^^^^^^^^^^^^^^^^^^^^^^^^
  File "/cluster/software/stacks/2024-06/spack/opt/spack/linux-ubuntu22.04-x86_64_v3/gcc-12.2.0/python-3.11.6-ukhwpjnwzzzizek3pgr75zkbhxros5fq/lib/python3.11/site-packages/pandas/core/algorithms.py", line 401, in unique
    return unique_with_mask(values)
           ^^^^^^^^^^^^^^^^^^^^^^^^
  File "/cluster/software/stacks/2024-06/spack/opt/spack/linux-ubuntu22.04-x86_64_v3/gcc-12.2.0/python-3.11.6-ukhwpjnwzzzizek3pgr75zkbhxros5fq/lib/python3.11/site-packages/pandas/core/algorithms.py", line 440, in unique_with_mask
    uniques = table.unique(values)
              ^^^^^^^^^^^^^^^^^^^^
  File "pandas/_libs/hashtable_class_helper.pxi", line 7248, in pandas._libs.hashtable.PyObjectHashTable.unique
  File "pandas/_libs/hashtable_class_helper.pxi", line 7195, in pandas._libs.hashtable.PyObjectHashTable._unique
TypeError: unhashable type: 'jaxlib.xla_extension.ArrayImpl'
srun: error: eu-g9-043-2: task 0: Exited with exit code 1
/var/spool/slurm/slurmd/state/job17971929/slurm_script: line 70: echo: write error: Stale file handle
